[2023-04-25T23:24:24.862+0000] {taskinstance.py:1090} INFO - Dependencies all met for dep_context=non-requeueable deps ti=<TaskInstance: treino-02.get-data manual__2023-04-25T23:19:46.165597+00:00 [queued]>
[2023-04-25T23:24:26.091+0000] {taskinstance.py:1090} INFO - Dependencies all met for dep_context=requeueable deps ti=<TaskInstance: treino-02.get-data manual__2023-04-25T23:19:46.165597+00:00 [queued]>
[2023-04-25T23:24:26.186+0000] {taskinstance.py:1288} INFO - 
--------------------------------------------------------------------------------
[2023-04-25T23:24:26.206+0000] {taskinstance.py:1289} INFO - Starting attempt 1 of 2
[2023-04-25T23:24:26.233+0000] {taskinstance.py:1290} INFO - 
--------------------------------------------------------------------------------
[2023-04-25T23:24:27.804+0000] {taskinstance.py:1309} INFO - Executing <Task(BashOperator): get-data> on 2023-04-25 23:19:46.165597+00:00
[2023-04-25T23:24:28.990+0000] {standard_task_runner.py:55} INFO - Started process 108 to run task
[2023-04-25T23:24:29.937+0000] {standard_task_runner.py:82} INFO - Running: ['***', 'tasks', 'run', 'treino-02', 'get-data', 'manual__2023-04-25T23:19:46.165597+00:00', '--job-id', '38', '--raw', '--subdir', 'DAGS_FOLDER/treino02.py', '--cfg-path', '/tmp/tmpnd4mzs87']
[2023-04-25T23:24:29.986+0000] {standard_task_runner.py:83} INFO - Job 38: Subtask get-data
[2023-04-25T23:24:34.064+0000] {task_command.py:389} INFO - Running <TaskInstance: treino-02.get-data manual__2023-04-25T23:19:46.165597+00:00 [running]> on host b7947b05bca0
[2023-04-25T23:24:36.897+0000] {taskinstance.py:1518} INFO - Exporting the following env vars:
AIRFLOW_CTX_DAG_EMAIL=test@example.com,test2@example.com
AIRFLOW_CTX_DAG_OWNER=augsmachado
AIRFLOW_CTX_DAG_ID=treino-02
AIRFLOW_CTX_TASK_ID=get-data
AIRFLOW_CTX_EXECUTION_DATE=2023-04-25T23:19:46.165597+00:00
AIRFLOW_CTX_TRY_NUMBER=1
AIRFLOW_CTX_DAG_RUN_ID=manual__2023-04-25T23:19:46.165597+00:00
[2023-04-25T23:24:37.212+0000] {subprocess.py:63} INFO - Tmp dir root location: 
 /tmp
[2023-04-25T23:24:37.284+0000] {subprocess.py:75} INFO - Running command: ['/bin/bash', '-c', 'curl https://raw.githubusercontent.com/datasciencedojo/datasets/master/titanic.csv -o ~/Users/augsmachado/Desktop/Development/***-docker/files/train.csv']
[2023-04-25T23:24:39.016+0000] {subprocess.py:86} INFO - Output:
[2023-04-25T23:24:39.955+0000] {subprocess.py:93} INFO -   % Total    % Received % Xferd  Average Speed   Time    Time     Time  Current
[2023-04-25T23:24:40.150+0000] {subprocess.py:93} INFO -                                  Dload  Upload   Total   Spent    Left  Speed
[2023-04-25T23:24:40.677+0000] {subprocess.py:93} INFO -   0     0    0     0    0     0      0      0 --:--:-- --:--:-- --:--:--     0  0     0    0     0    0     0      0      0 --:--:-- --:--:-- --:--:--     0Warning: Failed to create the file
[2023-04-25T23:24:40.841+0000] {subprocess.py:93} INFO - Warning: /home/***/Users/augsmachado/Desktop/Development/***-docker/fil
[2023-04-25T23:24:40.858+0000] {subprocess.py:93} INFO - Warning: es/train.csv: No such file or directory
[2023-04-25T23:24:40.872+0000] {subprocess.py:93} INFO -   1 60302    1   903    0     0   1095      0  0:00:55 --:--:--  0:00:55  1095
[2023-04-25T23:24:40.954+0000] {subprocess.py:93} INFO - curl: (23) Failure writing output to destination
[2023-04-25T23:24:41.813+0000] {subprocess.py:97} INFO - Command exited with return code 23
[2023-04-25T23:24:43.388+0000] {taskinstance.py:1776} ERROR - Task failed with exception
Traceback (most recent call last):
  File "/home/airflow/.local/lib/python3.7/site-packages/airflow/operators/bash.py", line 197, in execute
    f"Bash command failed. The command returned a non-zero exit code {result.exit_code}."
airflow.exceptions.AirflowException: Bash command failed. The command returned a non-zero exit code 23.
[2023-04-25T23:24:43.871+0000] {taskinstance.py:1332} INFO - Marking task as UP_FOR_RETRY. dag_id=treino-02, task_id=get-data, execution_date=20230425T231946, start_date=20230425T232425, end_date=20230425T232443
[2023-04-25T23:24:45.201+0000] {standard_task_runner.py:105} ERROR - Failed to execute job 38 for task get-data (Bash command failed. The command returned a non-zero exit code 23.; 108)
[2023-04-25T23:24:45.710+0000] {local_task_job.py:212} INFO - Task exited with return code 1
[2023-04-25T23:24:46.504+0000] {taskinstance.py:2596} INFO - 0 downstream tasks scheduled from follow-on schedule check
