[2023-04-25T23:30:52.798+0000] {taskinstance.py:1090} INFO - Dependencies all met for dep_context=non-requeueable deps ti=<TaskInstance: treino-02.get-data scheduled__2023-04-25T23:28:00+00:00 [queued]>
[2023-04-25T23:30:52.915+0000] {taskinstance.py:1090} INFO - Dependencies all met for dep_context=requeueable deps ti=<TaskInstance: treino-02.get-data scheduled__2023-04-25T23:28:00+00:00 [queued]>
[2023-04-25T23:30:52.921+0000] {taskinstance.py:1288} INFO - 
--------------------------------------------------------------------------------
[2023-04-25T23:30:52.923+0000] {taskinstance.py:1289} INFO - Starting attempt 1 of 2
[2023-04-25T23:30:52.925+0000] {taskinstance.py:1290} INFO - 
--------------------------------------------------------------------------------
[2023-04-25T23:30:53.253+0000] {taskinstance.py:1309} INFO - Executing <Task(BashOperator): get-data> on 2023-04-25 23:28:00+00:00
[2023-04-25T23:30:53.267+0000] {standard_task_runner.py:55} INFO - Started process 685 to run task
[2023-04-25T23:30:53.336+0000] {standard_task_runner.py:82} INFO - Running: ['***', 'tasks', 'run', 'treino-02', 'get-data', 'scheduled__2023-04-25T23:28:00+00:00', '--job-id', '131', '--raw', '--subdir', 'DAGS_FOLDER/treino02.py', '--cfg-path', '/tmp/tmpgxqnapp2']
[2023-04-25T23:30:53.339+0000] {standard_task_runner.py:83} INFO - Job 131: Subtask get-data
[2023-04-25T23:30:54.550+0000] {task_command.py:389} INFO - Running <TaskInstance: treino-02.get-data scheduled__2023-04-25T23:28:00+00:00 [running]> on host b7947b05bca0
[2023-04-25T23:30:56.496+0000] {taskinstance.py:1518} INFO - Exporting the following env vars:
AIRFLOW_CTX_DAG_EMAIL=test@example.com,test2@example.com
AIRFLOW_CTX_DAG_OWNER=augsmachado
AIRFLOW_CTX_DAG_ID=treino-02
AIRFLOW_CTX_TASK_ID=get-data
AIRFLOW_CTX_EXECUTION_DATE=2023-04-25T23:28:00+00:00
AIRFLOW_CTX_TRY_NUMBER=1
AIRFLOW_CTX_DAG_RUN_ID=scheduled__2023-04-25T23:28:00+00:00
[2023-04-25T23:30:56.716+0000] {subprocess.py:63} INFO - Tmp dir root location: 
 /tmp
[2023-04-25T23:30:56.777+0000] {subprocess.py:75} INFO - Running command: ['/bin/bash', '-c', 'curl -o ~/Users/augsmachado/Desktop/Development/***-docker/files/titanic.csv https://raw.githubusercontent.com/datasciencedojo/datasets/master/titanic.csv']
[2023-04-25T23:30:57.040+0000] {subprocess.py:86} INFO - Output:
[2023-04-25T23:30:57.553+0000] {subprocess.py:93} INFO -   % Total    % Received % Xferd  Average Speed   Time    Time     Time  Current
[2023-04-25T23:30:57.591+0000] {subprocess.py:93} INFO -                                  Dload  Upload   Total   Spent    Left  Speed
[2023-04-25T23:30:57.809+0000] {subprocess.py:93} INFO -   0     0    0     0    0     0      0      0 --:--:-- --:--:-- --:--:--     0Warning: Failed to create the file
[2023-04-25T23:30:57.813+0000] {subprocess.py:93} INFO - Warning: /home/***/Users/augsmachado/Desktop/Development/***-docker/fil
[2023-04-25T23:30:57.818+0000] {subprocess.py:93} INFO - Warning: es/titanic.csv: No such file or directory
[2023-04-25T23:30:57.820+0000] {subprocess.py:93} INFO -   1 60302    1   858    0     0   3287      0  0:00:18 --:--:--  0:00:18  3300
[2023-04-25T23:30:57.833+0000] {subprocess.py:93} INFO - curl: (23) Failure writing output to destination
[2023-04-25T23:30:57.836+0000] {subprocess.py:97} INFO - Command exited with return code 23
[2023-04-25T23:30:57.977+0000] {taskinstance.py:1776} ERROR - Task failed with exception
Traceback (most recent call last):
  File "/home/airflow/.local/lib/python3.7/site-packages/airflow/operators/bash.py", line 197, in execute
    f"Bash command failed. The command returned a non-zero exit code {result.exit_code}."
airflow.exceptions.AirflowException: Bash command failed. The command returned a non-zero exit code 23.
[2023-04-25T23:30:58.049+0000] {taskinstance.py:1332} INFO - Marking task as UP_FOR_RETRY. dag_id=treino-02, task_id=get-data, execution_date=20230425T232800, start_date=20230425T233052, end_date=20230425T233058
[2023-04-25T23:30:59.966+0000] {standard_task_runner.py:105} ERROR - Failed to execute job 131 for task get-data (Bash command failed. The command returned a non-zero exit code 23.; 685)
[2023-04-25T23:31:01.063+0000] {local_task_job.py:212} INFO - Task exited with return code 1
[2023-04-25T23:31:01.776+0000] {taskinstance.py:2596} INFO - 0 downstream tasks scheduled from follow-on schedule check
