[2023-04-25T23:32:50.879+0000] {taskinstance.py:1090} INFO - Dependencies all met for dep_context=non-requeueable deps ti=<TaskInstance: treino-02.get-data scheduled__2023-04-23T21:30:00+00:00 [queued]>
[2023-04-25T23:32:50.972+0000] {taskinstance.py:1090} INFO - Dependencies all met for dep_context=requeueable deps ti=<TaskInstance: treino-02.get-data scheduled__2023-04-23T21:30:00+00:00 [queued]>
[2023-04-25T23:32:50.973+0000] {taskinstance.py:1288} INFO - 
--------------------------------------------------------------------------------
[2023-04-25T23:32:50.975+0000] {taskinstance.py:1289} INFO - Starting attempt 1 of 2
[2023-04-25T23:32:50.976+0000] {taskinstance.py:1290} INFO - 
--------------------------------------------------------------------------------
[2023-04-25T23:32:52.194+0000] {taskinstance.py:1309} INFO - Executing <Task(BashOperator): get-data> on 2023-04-23 21:30:00+00:00
[2023-04-25T23:32:52.302+0000] {standard_task_runner.py:55} INFO - Started process 918 to run task
[2023-04-25T23:32:52.327+0000] {standard_task_runner.py:82} INFO - Running: ['***', 'tasks', 'run', 'treino-02', 'get-data', 'scheduled__2023-04-23T21:30:00+00:00', '--job-id', '168', '--raw', '--subdir', 'DAGS_FOLDER/treino02.py', '--cfg-path', '/tmp/tmpt7bq2ry2']
[2023-04-25T23:32:52.332+0000] {standard_task_runner.py:83} INFO - Job 168: Subtask get-data
[2023-04-25T23:32:54.323+0000] {task_command.py:389} INFO - Running <TaskInstance: treino-02.get-data scheduled__2023-04-23T21:30:00+00:00 [running]> on host b7947b05bca0
[2023-04-25T23:32:58.282+0000] {taskinstance.py:1518} INFO - Exporting the following env vars:
AIRFLOW_CTX_DAG_EMAIL=test@example.com,test2@example.com
AIRFLOW_CTX_DAG_OWNER=augsmachado
AIRFLOW_CTX_DAG_ID=treino-02
AIRFLOW_CTX_TASK_ID=get-data
AIRFLOW_CTX_EXECUTION_DATE=2023-04-23T21:30:00+00:00
AIRFLOW_CTX_TRY_NUMBER=1
AIRFLOW_CTX_DAG_RUN_ID=scheduled__2023-04-23T21:30:00+00:00
[2023-04-25T23:32:58.771+0000] {subprocess.py:63} INFO - Tmp dir root location: 
 /tmp
[2023-04-25T23:32:58.864+0000] {subprocess.py:75} INFO - Running command: ['/bin/bash', '-c', 'curl -o ~/Users/augsmachado/Desktop/Development/***-docker/files/titanic.csv https://raw.githubusercontent.com/datasciencedojo/datasets/master/titanic.csv']
[2023-04-25T23:32:59.478+0000] {subprocess.py:86} INFO - Output:
[2023-04-25T23:33:00.189+0000] {subprocess.py:93} INFO -   % Total    % Received % Xferd  Average Speed   Time    Time     Time  Current
[2023-04-25T23:33:00.207+0000] {subprocess.py:93} INFO -                                  Dload  Upload   Total   Spent    Left  Speed
[2023-04-25T23:33:01.299+0000] {subprocess.py:93} INFO -   0     0    0     0    0     0      0      0 --:--:-- --:--:-- --:--:--     0  0     0    0     0    0     0      0      0 --:--:--  0:00:01 --:--:--     0Warning: Failed to create the file
[2023-04-25T23:33:01.440+0000] {subprocess.py:93} INFO - Warning: /home/***/Users/augsmachado/Desktop/Development/***-docker/fil
[2023-04-25T23:33:01.453+0000] {subprocess.py:93} INFO - Warning: es/titanic.csv: No such file or directory
[2023-04-25T23:33:01.497+0000] {subprocess.py:93} INFO -   2 60302    2  1413    0     0   1244      0  0:00:48  0:00:01  0:00:47  1246
[2023-04-25T23:33:01.509+0000] {subprocess.py:93} INFO - curl: (23) Failure writing output to destination
[2023-04-25T23:33:01.993+0000] {subprocess.py:97} INFO - Command exited with return code 23
[2023-04-25T23:33:03.002+0000] {taskinstance.py:1776} ERROR - Task failed with exception
Traceback (most recent call last):
  File "/home/airflow/.local/lib/python3.7/site-packages/airflow/operators/bash.py", line 197, in execute
    f"Bash command failed. The command returned a non-zero exit code {result.exit_code}."
airflow.exceptions.AirflowException: Bash command failed. The command returned a non-zero exit code 23.
[2023-04-25T23:33:03.080+0000] {taskinstance.py:1332} INFO - Marking task as UP_FOR_RETRY. dag_id=treino-02, task_id=get-data, execution_date=20230423T213000, start_date=20230425T233250, end_date=20230425T233303
[2023-04-25T23:33:03.353+0000] {standard_task_runner.py:105} ERROR - Failed to execute job 168 for task get-data (Bash command failed. The command returned a non-zero exit code 23.; 918)
[2023-04-25T23:33:03.976+0000] {local_task_job.py:212} INFO - Task exited with return code 1
[2023-04-25T23:33:29.130+0000] {taskinstance.py:2596} INFO - 0 downstream tasks scheduled from follow-on schedule check
