[2023-06-11T03:25:34.524+0000] {taskinstance.py:1090} INFO - Dependencies all met for dep_context=non-requeueable deps ti=<TaskInstance: treino-06.is_api-active scheduled__2023-06-10T00:00:00+00:00 [queued]>
[2023-06-11T03:25:34.610+0000] {taskinstance.py:1090} INFO - Dependencies all met for dep_context=requeueable deps ti=<TaskInstance: treino-06.is_api-active scheduled__2023-06-10T00:00:00+00:00 [queued]>
[2023-06-11T03:25:34.612+0000] {taskinstance.py:1288} INFO - 
--------------------------------------------------------------------------------
[2023-06-11T03:25:34.613+0000] {taskinstance.py:1289} INFO - Starting attempt 1 of 1
[2023-06-11T03:25:34.614+0000] {taskinstance.py:1290} INFO - 
--------------------------------------------------------------------------------
[2023-06-11T03:25:34.756+0000] {taskinstance.py:1309} INFO - Executing <Task(HttpSensor): is_api-active> on 2023-06-10 00:00:00+00:00
[2023-06-11T03:25:34.811+0000] {standard_task_runner.py:82} INFO - Running: ['***', 'tasks', 'run', 'treino-06', 'is_api-active', 'scheduled__2023-06-10T00:00:00+00:00', '--job-id', '409', '--raw', '--subdir', 'DAGS_FOLDER/treino06.py', '--cfg-path', '/tmp/tmp6kv2q2nf']
[2023-06-11T03:25:34.818+0000] {standard_task_runner.py:83} INFO - Job 409: Subtask is_api-active
[2023-06-11T03:25:34.800+0000] {standard_task_runner.py:55} INFO - Started process 65 to run task
[2023-06-11T03:25:35.187+0000] {task_command.py:389} INFO - Running <TaskInstance: treino-06.is_api-active scheduled__2023-06-10T00:00:00+00:00 [running]> on host b7947b05bca0
[2023-06-11T03:25:35.615+0000] {taskinstance.py:1518} INFO - Exporting the following env vars:
AIRFLOW_CTX_DAG_OWNER=***
AIRFLOW_CTX_DAG_ID=treino-06
AIRFLOW_CTX_TASK_ID=is_api-active
AIRFLOW_CTX_EXECUTION_DATE=2023-06-10T00:00:00+00:00
AIRFLOW_CTX_TRY_NUMBER=1
AIRFLOW_CTX_DAG_RUN_ID=scheduled__2023-06-10T00:00:00+00:00
[2023-06-11T03:25:35.631+0000] {http.py:122} INFO - Poking: 
[2023-06-11T03:25:35.680+0000] {base.py:73} INFO - Using connection ID 'treino_06_api_posts' for task execution.
[2023-06-11T03:25:35.727+0000] {http.py:215} WARNING - HTTPSConnectionPool(host='webhook.site', port=443): Max retries exceeded with url: /b02b6e97-2602-4b5b-acfe-fbcd97e2dd85 (Caused by NewConnectionError('<urllib3.connection.HTTPSConnection object at 0xffff9d4d8f90>: Failed to establish a new connection: [Errno -2] Name or service not known')) Tenacity will retry to execute the operation
[2023-06-11T03:25:35.732+0000] {taskinstance.py:1776} ERROR - Task failed with exception
Traceback (most recent call last):
  File "/home/airflow/.local/lib/python3.7/site-packages/urllib3/connection.py", line 175, in _new_conn
    (self._dns_host, self.port), self.timeout, **extra_kw
  File "/home/airflow/.local/lib/python3.7/site-packages/urllib3/util/connection.py", line 72, in create_connection
    for res in socket.getaddrinfo(host, port, family, socket.SOCK_STREAM):
  File "/usr/local/lib/python3.7/socket.py", line 752, in getaddrinfo
    for res in _socket.getaddrinfo(host, port, family, type, proto, flags):
socket.gaierror: [Errno -2] Name or service not known

During handling of the above exception, another exception occurred:

Traceback (most recent call last):
  File "/home/airflow/.local/lib/python3.7/site-packages/urllib3/connectionpool.py", line 710, in urlopen
    chunked=chunked,
  File "/home/airflow/.local/lib/python3.7/site-packages/urllib3/connectionpool.py", line 386, in _make_request
    self._validate_conn(conn)
  File "/home/airflow/.local/lib/python3.7/site-packages/urllib3/connectionpool.py", line 1042, in _validate_conn
    conn.connect()
  File "/home/airflow/.local/lib/python3.7/site-packages/urllib3/connection.py", line 363, in connect
    self.sock = conn = self._new_conn()
  File "/home/airflow/.local/lib/python3.7/site-packages/urllib3/connection.py", line 187, in _new_conn
    self, "Failed to establish a new connection: %s" % e
urllib3.exceptions.NewConnectionError: <urllib3.connection.HTTPSConnection object at 0xffff9d4d8f90>: Failed to establish a new connection: [Errno -2] Name or service not known

During handling of the above exception, another exception occurred:

Traceback (most recent call last):
  File "/home/airflow/.local/lib/python3.7/site-packages/requests/adapters.py", line 499, in send
    timeout=timeout,
  File "/home/airflow/.local/lib/python3.7/site-packages/urllib3/connectionpool.py", line 788, in urlopen
    method, url, error=e, _pool=self, _stacktrace=sys.exc_info()[2]
  File "/home/airflow/.local/lib/python3.7/site-packages/urllib3/util/retry.py", line 592, in increment
    raise MaxRetryError(_pool, url, error or ResponseError(cause))
urllib3.exceptions.MaxRetryError: HTTPSConnectionPool(host='webhook.site', port=443): Max retries exceeded with url: /b02b6e97-2602-4b5b-acfe-fbcd97e2dd85 (Caused by NewConnectionError('<urllib3.connection.HTTPSConnection object at 0xffff9d4d8f90>: Failed to establish a new connection: [Errno -2] Name or service not known'))

During handling of the above exception, another exception occurred:

Traceback (most recent call last):
  File "/home/airflow/.local/lib/python3.7/site-packages/airflow/sensors/base.py", line 199, in execute
    poke_return = self.poke(context)
  File "/home/airflow/.local/lib/python3.7/site-packages/airflow/providers/http/sensors/http.py", line 128, in poke
    extra_options=self.extra_options,
  File "/home/airflow/.local/lib/python3.7/site-packages/airflow/providers/http/hooks/http.py", line 158, in run
    return self.run_and_check(session, prepped_request, extra_options)
  File "/home/airflow/.local/lib/python3.7/site-packages/airflow/providers/http/hooks/http.py", line 216, in run_and_check
    raise ex
  File "/home/airflow/.local/lib/python3.7/site-packages/airflow/providers/http/hooks/http.py", line 208, in run_and_check
    response = session.send(prepped_request, **send_kwargs)
  File "/home/airflow/.local/lib/python3.7/site-packages/requests/sessions.py", line 701, in send
    r = adapter.send(request, **kwargs)
  File "/home/airflow/.local/lib/python3.7/site-packages/requests/adapters.py", line 565, in send
    raise ConnectionError(e, request=request)
requests.exceptions.ConnectionError: HTTPSConnectionPool(host='webhook.site', port=443): Max retries exceeded with url: /b02b6e97-2602-4b5b-acfe-fbcd97e2dd85 (Caused by NewConnectionError('<urllib3.connection.HTTPSConnection object at 0xffff9d4d8f90>: Failed to establish a new connection: [Errno -2] Name or service not known'))
[2023-06-11T03:25:35.781+0000] {taskinstance.py:1332} INFO - Marking task as FAILED. dag_id=treino-06, task_id=is_api-active, execution_date=20230610T000000, start_date=20230611T032534, end_date=20230611T032535
[2023-06-11T03:25:35.873+0000] {standard_task_runner.py:105} ERROR - Failed to execute job 409 for task is_api-active (HTTPSConnectionPool(host='webhook.site', port=443): Max retries exceeded with url: /b02b6e97-2602-4b5b-acfe-fbcd97e2dd85 (Caused by NewConnectionError('<urllib3.connection.HTTPSConnection object at 0xffff9d4d8f90>: Failed to establish a new connection: [Errno -2] Name or service not known')); 65)
[2023-06-11T03:25:35.973+0000] {local_task_job.py:212} INFO - Task exited with return code 1
