[2023-04-25T23:26:54.251+0000] {taskinstance.py:1090} INFO - Dependencies all met for dep_context=non-requeueable deps ti=<TaskInstance: treino-02.get-data scheduled__2023-04-25T23:22:00+00:00 [queued]>
[2023-04-25T23:26:54.259+0000] {taskinstance.py:1090} INFO - Dependencies all met for dep_context=requeueable deps ti=<TaskInstance: treino-02.get-data scheduled__2023-04-25T23:22:00+00:00 [queued]>
[2023-04-25T23:26:54.260+0000] {taskinstance.py:1288} INFO - 
--------------------------------------------------------------------------------
[2023-04-25T23:26:54.261+0000] {taskinstance.py:1289} INFO - Starting attempt 2 of 2
[2023-04-25T23:26:54.261+0000] {taskinstance.py:1290} INFO - 
--------------------------------------------------------------------------------
[2023-04-25T23:26:54.274+0000] {taskinstance.py:1309} INFO - Executing <Task(BashOperator): get-data> on 2023-04-25 23:22:00+00:00
[2023-04-25T23:26:54.283+0000] {standard_task_runner.py:55} INFO - Started process 350 to run task
[2023-04-25T23:26:54.289+0000] {standard_task_runner.py:82} INFO - Running: ['***', 'tasks', 'run', 'treino-02', 'get-data', 'scheduled__2023-04-25T23:22:00+00:00', '--job-id', '77', '--raw', '--subdir', 'DAGS_FOLDER/treino02.py', '--cfg-path', '/tmp/tmpw_6s5gyv']
[2023-04-25T23:26:54.290+0000] {standard_task_runner.py:83} INFO - Job 77: Subtask get-data
[2023-04-25T23:26:54.405+0000] {task_command.py:389} INFO - Running <TaskInstance: treino-02.get-data scheduled__2023-04-25T23:22:00+00:00 [running]> on host b7947b05bca0
[2023-04-25T23:26:54.496+0000] {taskinstance.py:1518} INFO - Exporting the following env vars:
AIRFLOW_CTX_DAG_EMAIL=test@example.com,test2@example.com
AIRFLOW_CTX_DAG_OWNER=augsmachado
AIRFLOW_CTX_DAG_ID=treino-02
AIRFLOW_CTX_TASK_ID=get-data
AIRFLOW_CTX_EXECUTION_DATE=2023-04-25T23:22:00+00:00
AIRFLOW_CTX_TRY_NUMBER=2
AIRFLOW_CTX_DAG_RUN_ID=scheduled__2023-04-25T23:22:00+00:00
[2023-04-25T23:26:54.501+0000] {subprocess.py:63} INFO - Tmp dir root location: 
 /tmp
[2023-04-25T23:26:54.502+0000] {subprocess.py:75} INFO - Running command: ['/bin/bash', '-c', 'curl https://raw.githubusercontent.com/datasciencedojo/datasets/master/titanic.csv -o ~/Users/augsmachado/Desktop/Development/***-docker/files/titanic.csv']
[2023-04-25T23:26:54.536+0000] {subprocess.py:86} INFO - Output:
[2023-04-25T23:26:54.570+0000] {subprocess.py:93} INFO -   % Total    % Received % Xferd  Average Speed   Time    Time     Time  Current
[2023-04-25T23:26:54.571+0000] {subprocess.py:93} INFO -                                  Dload  Upload   Total   Spent    Left  Speed
[2023-04-25T23:26:54.711+0000] {subprocess.py:93} INFO -   0     0    0     0    0     0      0      0 --:--:-- --:--:-- --:--:--     0Warning: Failed to create the file
[2023-04-25T23:26:54.712+0000] {subprocess.py:93} INFO - Warning: /home/***/Users/augsmachado/Desktop/Development/***-docker/fil
[2023-04-25T23:26:54.715+0000] {subprocess.py:93} INFO - Warning: es/titanic.csv: No such file or directory
[2023-04-25T23:26:54.716+0000] {subprocess.py:93} INFO -   1 60302    1   859    0     0   6092      0  0:00:09 --:--:--  0:00:09  6092
[2023-04-25T23:26:54.717+0000] {subprocess.py:93} INFO - curl: (23) Failure writing output to destination
[2023-04-25T23:26:54.718+0000] {subprocess.py:97} INFO - Command exited with return code 23
[2023-04-25T23:26:54.747+0000] {taskinstance.py:1776} ERROR - Task failed with exception
Traceback (most recent call last):
  File "/home/airflow/.local/lib/python3.7/site-packages/airflow/operators/bash.py", line 197, in execute
    f"Bash command failed. The command returned a non-zero exit code {result.exit_code}."
airflow.exceptions.AirflowException: Bash command failed. The command returned a non-zero exit code 23.
[2023-04-25T23:26:54.753+0000] {taskinstance.py:1332} INFO - Marking task as FAILED. dag_id=treino-02, task_id=get-data, execution_date=20230425T232200, start_date=20230425T232654, end_date=20230425T232654
[2023-04-25T23:26:54.783+0000] {standard_task_runner.py:105} ERROR - Failed to execute job 77 for task get-data (Bash command failed. The command returned a non-zero exit code 23.; 350)
[2023-04-25T23:26:54.825+0000] {local_task_job.py:212} INFO - Task exited with return code 1
[2023-04-25T23:26:54.866+0000] {taskinstance.py:2596} INFO - 0 downstream tasks scheduled from follow-on schedule check
