[2023-04-25T23:25:50.596+0000] {taskinstance.py:1090} INFO - Dependencies all met for dep_context=non-requeueable deps ti=<TaskInstance: treino-02.get-data manual__2023-04-25T23:17:10.450519+00:00 [queued]>
[2023-04-25T23:25:50.608+0000] {taskinstance.py:1090} INFO - Dependencies all met for dep_context=requeueable deps ti=<TaskInstance: treino-02.get-data manual__2023-04-25T23:17:10.450519+00:00 [queued]>
[2023-04-25T23:25:50.609+0000] {taskinstance.py:1288} INFO - 
--------------------------------------------------------------------------------
[2023-04-25T23:25:50.609+0000] {taskinstance.py:1289} INFO - Starting attempt 2 of 2
[2023-04-25T23:25:50.610+0000] {taskinstance.py:1290} INFO - 
--------------------------------------------------------------------------------
[2023-04-25T23:25:50.630+0000] {taskinstance.py:1309} INFO - Executing <Task(BashOperator): get-data> on 2023-04-25 23:17:10.450519+00:00
[2023-04-25T23:25:50.647+0000] {standard_task_runner.py:55} INFO - Started process 226 to run task
[2023-04-25T23:25:50.682+0000] {standard_task_runner.py:82} INFO - Running: ['***', 'tasks', 'run', 'treino-02', 'get-data', 'manual__2023-04-25T23:17:10.450519+00:00', '--job-id', '56', '--raw', '--subdir', 'DAGS_FOLDER/treino02.py', '--cfg-path', '/tmp/tmp5vakum5n']
[2023-04-25T23:25:50.684+0000] {standard_task_runner.py:83} INFO - Job 56: Subtask get-data
[2023-04-25T23:25:50.869+0000] {task_command.py:389} INFO - Running <TaskInstance: treino-02.get-data manual__2023-04-25T23:17:10.450519+00:00 [running]> on host b7947b05bca0
[2023-04-25T23:25:51.111+0000] {taskinstance.py:1518} INFO - Exporting the following env vars:
AIRFLOW_CTX_DAG_EMAIL=test@example.com,test2@example.com
AIRFLOW_CTX_DAG_OWNER=augsmachado
AIRFLOW_CTX_DAG_ID=treino-02
AIRFLOW_CTX_TASK_ID=get-data
AIRFLOW_CTX_EXECUTION_DATE=2023-04-25T23:17:10.450519+00:00
AIRFLOW_CTX_TRY_NUMBER=2
AIRFLOW_CTX_DAG_RUN_ID=manual__2023-04-25T23:17:10.450519+00:00
[2023-04-25T23:25:51.141+0000] {subprocess.py:63} INFO - Tmp dir root location: 
 /tmp
[2023-04-25T23:25:51.143+0000] {subprocess.py:75} INFO - Running command: ['/bin/bash', '-c', 'curl https://raw.githubusercontent.com/datasciencedojo/datasets/master/titanic.csv -o ~/Users/augsmachado/Desktop/Development/***-docker/files/train.csv']
[2023-04-25T23:25:51.187+0000] {subprocess.py:86} INFO - Output:
[2023-04-25T23:25:51.241+0000] {subprocess.py:93} INFO -   % Total    % Received % Xferd  Average Speed   Time    Time     Time  Current
[2023-04-25T23:25:51.244+0000] {subprocess.py:93} INFO -                                  Dload  Upload   Total   Spent    Left  Speed
[2023-04-25T23:25:51.657+0000] {subprocess.py:93} INFO -   0     0    0     0    0     0      0      0 --:--:-- --:--:-- --:--:--     0Warning: Failed to create the file
[2023-04-25T23:25:51.659+0000] {subprocess.py:93} INFO - Warning: /home/***/Users/augsmachado/Desktop/Development/***-docker/fil
[2023-04-25T23:25:51.660+0000] {subprocess.py:93} INFO - Warning: es/train.csv: No such file or directory
[2023-04-25T23:25:51.661+0000] {subprocess.py:93} INFO -   1 60302    1   859    0     0   2064      0  0:00:29 --:--:--  0:00:29  2064
[2023-04-25T23:25:51.661+0000] {subprocess.py:93} INFO - curl: (23) Failure writing output to destination
[2023-04-25T23:25:51.663+0000] {subprocess.py:97} INFO - Command exited with return code 23
[2023-04-25T23:25:51.698+0000] {taskinstance.py:1776} ERROR - Task failed with exception
Traceback (most recent call last):
  File "/home/airflow/.local/lib/python3.7/site-packages/airflow/operators/bash.py", line 197, in execute
    f"Bash command failed. The command returned a non-zero exit code {result.exit_code}."
airflow.exceptions.AirflowException: Bash command failed. The command returned a non-zero exit code 23.
[2023-04-25T23:25:51.716+0000] {taskinstance.py:1332} INFO - Marking task as FAILED. dag_id=treino-02, task_id=get-data, execution_date=20230425T231710, start_date=20230425T232550, end_date=20230425T232551
[2023-04-25T23:25:51.768+0000] {standard_task_runner.py:105} ERROR - Failed to execute job 56 for task get-data (Bash command failed. The command returned a non-zero exit code 23.; 226)
[2023-04-25T23:25:51.826+0000] {local_task_job.py:212} INFO - Task exited with return code 1
[2023-04-25T23:25:51.871+0000] {taskinstance.py:2596} INFO - 0 downstream tasks scheduled from follow-on schedule check
