[2023-04-25T23:29:58.712+0000] {taskinstance.py:1090} INFO - Dependencies all met for dep_context=non-requeueable deps ti=<TaskInstance: treino-02.get-data scheduled__2023-04-25T23:26:00+00:00 [queued]>
[2023-04-25T23:30:00.278+0000] {taskinstance.py:1090} INFO - Dependencies all met for dep_context=requeueable deps ti=<TaskInstance: treino-02.get-data scheduled__2023-04-25T23:26:00+00:00 [queued]>
[2023-04-25T23:30:00.360+0000] {taskinstance.py:1288} INFO - 
--------------------------------------------------------------------------------
[2023-04-25T23:30:00.424+0000] {taskinstance.py:1289} INFO - Starting attempt 2 of 2
[2023-04-25T23:30:00.452+0000] {taskinstance.py:1290} INFO - 
--------------------------------------------------------------------------------
[2023-04-25T23:30:01.889+0000] {taskinstance.py:1309} INFO - Executing <Task(BashOperator): get-data> on 2023-04-25 23:26:00+00:00
[2023-04-25T23:30:02.421+0000] {standard_task_runner.py:55} INFO - Started process 636 to run task
[2023-04-25T23:30:02.586+0000] {standard_task_runner.py:82} INFO - Running: ['***', 'tasks', 'run', 'treino-02', 'get-data', 'scheduled__2023-04-25T23:26:00+00:00', '--job-id', '125', '--raw', '--subdir', 'DAGS_FOLDER/treino02.py', '--cfg-path', '/tmp/tmpejgc166i']
[2023-04-25T23:30:02.681+0000] {standard_task_runner.py:83} INFO - Job 125: Subtask get-data
[2023-04-25T23:30:07.302+0000] {task_command.py:389} INFO - Running <TaskInstance: treino-02.get-data scheduled__2023-04-25T23:26:00+00:00 [running]> on host b7947b05bca0
[2023-04-25T23:30:17.596+0000] {taskinstance.py:1518} INFO - Exporting the following env vars:
AIRFLOW_CTX_DAG_EMAIL=test@example.com,test2@example.com
AIRFLOW_CTX_DAG_OWNER=augsmachado
AIRFLOW_CTX_DAG_ID=treino-02
AIRFLOW_CTX_TASK_ID=get-data
AIRFLOW_CTX_EXECUTION_DATE=2023-04-25T23:26:00+00:00
AIRFLOW_CTX_TRY_NUMBER=2
AIRFLOW_CTX_DAG_RUN_ID=scheduled__2023-04-25T23:26:00+00:00
[2023-04-25T23:30:18.248+0000] {subprocess.py:63} INFO - Tmp dir root location: 
 /tmp
[2023-04-25T23:30:18.305+0000] {subprocess.py:75} INFO - Running command: ['/bin/bash', '-c', 'curl https://raw.githubusercontent.com/datasciencedojo/datasets/master/titanic.csv -o ~/Users/augsmachado/Desktop/Development/***-docker/files/titanic.csv']
[2023-04-25T23:30:18.926+0000] {subprocess.py:86} INFO - Output:
[2023-04-25T23:30:21.623+0000] {subprocess.py:93} INFO -   % Total    % Received % Xferd  Average Speed   Time    Time     Time  Current
[2023-04-25T23:30:21.637+0000] {subprocess.py:93} INFO -                                  Dload  Upload   Total   Spent    Left  Speed
[2023-04-25T23:30:21.997+0000] {subprocess.py:93} INFO -   0     0    0     0    0     0      0      0 --:--:-- --:--:-- --:--:--     0  0     0    0     0    0     0      0      0 --:--:-- --:--:-- --:--:--     0Warning: Failed to create the file
[2023-04-25T23:30:22.003+0000] {subprocess.py:93} INFO - Warning: /home/***/Users/augsmachado/Desktop/Development/***-docker/fil
[2023-04-25T23:30:22.005+0000] {subprocess.py:93} INFO - Warning: es/titanic.csv: No such file or directory
[2023-04-25T23:30:22.007+0000] {subprocess.py:93} INFO -   1 60302    1   858    0     0   2269      0  0:00:26 --:--:--  0:00:26  2263
[2023-04-25T23:30:22.009+0000] {subprocess.py:93} INFO - curl: (23) Failure writing output to destination
[2023-04-25T23:30:22.019+0000] {subprocess.py:97} INFO - Command exited with return code 23
[2023-04-25T23:30:22.172+0000] {taskinstance.py:1776} ERROR - Task failed with exception
Traceback (most recent call last):
  File "/home/airflow/.local/lib/python3.7/site-packages/airflow/operators/bash.py", line 197, in execute
    f"Bash command failed. The command returned a non-zero exit code {result.exit_code}."
airflow.exceptions.AirflowException: Bash command failed. The command returned a non-zero exit code 23.
[2023-04-25T23:30:22.230+0000] {taskinstance.py:1332} INFO - Marking task as FAILED. dag_id=treino-02, task_id=get-data, execution_date=20230425T232600, start_date=20230425T232958, end_date=20230425T233022
[2023-04-25T23:30:25.743+0000] {standard_task_runner.py:105} ERROR - Failed to execute job 125 for task get-data (Bash command failed. The command returned a non-zero exit code 23.; 636)
[2023-04-25T23:30:26.578+0000] {local_task_job.py:212} INFO - Task exited with return code 1
[2023-04-25T23:30:27.554+0000] {taskinstance.py:2596} INFO - 0 downstream tasks scheduled from follow-on schedule check
